2020-10-31 11:49:46,698 ERROR django.request:140491100808960 - Internal Server Error: /taskstest
Traceback (most recent call last):
  File "/usr/local/lib/python3.7/site-packages/django/core/handlers/exception.py", line 34, in inner
    response = get_response(request)
  File "/usr/local/lib/python3.7/site-packages/django/core/handlers/base.py", line 115, in _get_response
    response = self.process_exception_by_middleware(e, request)
  File "/usr/local/lib/python3.7/site-packages/django/core/handlers/base.py", line 113, in _get_response
    response = wrapped_callback(request, *callback_args, **callback_kwargs)
  File "/app/prs_dev/modules/views/event_collector.py", line 45, in main
    observer.start()
  File "/usr/local/lib/python3.7/site-packages/watchdog/observers/api.py", line 260, in start
    emitter.start()
  File "/usr/local/lib/python3.7/site-packages/watchdog/utils/__init__.py", line 110, in start
    self.on_thread_start()
  File "/usr/local/lib/python3.7/site-packages/watchdog/observers/inotify.py", line 121, in on_thread_start
    self._inotify = InotifyBuffer(path, self.watch.is_recursive)
  File "/usr/local/lib/python3.7/site-packages/watchdog/observers/inotify_buffer.py", line 35, in __init__
    self._inotify = Inotify(path, recursive)
  File "/usr/local/lib/python3.7/site-packages/watchdog/observers/inotify_c.py", line 203, in __init__
    self._add_watch(path, event_mask)
  File "/usr/local/lib/python3.7/site-packages/watchdog/observers/inotify_c.py", line 412, in _add_watch
    Inotify._raise_error()
  File "/usr/local/lib/python3.7/site-packages/watchdog/observers/inotify_c.py", line 432, in _raise_error
    raise OSError(err, os.strerror(err))
FileNotFoundError: [Errno 2] No such file or directory
2020-10-31 11:51:45,345 ERROR django.request:140153507018496 - Internal Server Error: /taskstest
Traceback (most recent call last):
  File "/usr/local/lib/python3.7/site-packages/django/core/handlers/exception.py", line 34, in inner
    response = get_response(request)
  File "/usr/local/lib/python3.7/site-packages/django/core/handlers/base.py", line 115, in _get_response
    response = self.process_exception_by_middleware(e, request)
  File "/usr/local/lib/python3.7/site-packages/django/core/handlers/base.py", line 113, in _get_response
    response = wrapped_callback(request, *callback_args, **callback_kwargs)
  File "/app/prs_dev/modules/views/event_collector.py", line 58, in main
    results = list(queryset.order_by('created_time').filter(is_done=False).values())
  File "/usr/local/lib/python3.7/site-packages/django/db/models/query.py", line 892, in filter
    return self._filter_or_exclude(False, *args, **kwargs)
  File "/usr/local/lib/python3.7/site-packages/django/db/models/query.py", line 910, in _filter_or_exclude
    clone.query.add_q(Q(*args, **kwargs))
  File "/usr/local/lib/python3.7/site-packages/django/db/models/sql/query.py", line 1290, in add_q
    clause, _ = self._add_q(q_object, self.used_aliases)
  File "/usr/local/lib/python3.7/site-packages/django/db/models/sql/query.py", line 1318, in _add_q
    split_subq=split_subq, simple_col=simple_col,
  File "/usr/local/lib/python3.7/site-packages/django/db/models/sql/query.py", line 1190, in build_filter
    lookups, parts, reffed_expression = self.solve_lookup_type(arg)
  File "/usr/local/lib/python3.7/site-packages/django/db/models/sql/query.py", line 1049, in solve_lookup_type
    _, field, _, lookup_parts = self.names_to_path(lookup_splitted, self.get_meta())
  File "/usr/local/lib/python3.7/site-packages/django/db/models/sql/query.py", line 1420, in names_to_path
    "Choices are: %s" % (name, ", ".join(available)))
django.core.exceptions.FieldError: Cannot resolve keyword 'is_done' into field. Choices are: created_time, file_path, file_size, filename, id, last_modified_time
2020-10-31 11:52:58,133 ERROR django.request:140153507018496 - Internal Server Error: /taskstest
Traceback (most recent call last):
  File "/usr/local/lib/python3.7/site-packages/django/core/handlers/exception.py", line 34, in inner
    response = get_response(request)
  File "/usr/local/lib/python3.7/site-packages/django/core/handlers/base.py", line 115, in _get_response
    response = self.process_exception_by_middleware(e, request)
  File "/usr/local/lib/python3.7/site-packages/django/core/handlers/base.py", line 113, in _get_response
    response = wrapped_callback(request, *callback_args, **callback_kwargs)
  File "/app/prs_dev/modules/views/event_collector.py", line 58, in main
    results = list(queryset.order_by('created_time').filter(is_done=False).values())
  File "/usr/local/lib/python3.7/site-packages/django/db/models/query.py", line 892, in filter
    return self._filter_or_exclude(False, *args, **kwargs)
  File "/usr/local/lib/python3.7/site-packages/django/db/models/query.py", line 910, in _filter_or_exclude
    clone.query.add_q(Q(*args, **kwargs))
  File "/usr/local/lib/python3.7/site-packages/django/db/models/sql/query.py", line 1290, in add_q
    clause, _ = self._add_q(q_object, self.used_aliases)
  File "/usr/local/lib/python3.7/site-packages/django/db/models/sql/query.py", line 1318, in _add_q
    split_subq=split_subq, simple_col=simple_col,
  File "/usr/local/lib/python3.7/site-packages/django/db/models/sql/query.py", line 1190, in build_filter
    lookups, parts, reffed_expression = self.solve_lookup_type(arg)
  File "/usr/local/lib/python3.7/site-packages/django/db/models/sql/query.py", line 1049, in solve_lookup_type
    _, field, _, lookup_parts = self.names_to_path(lookup_splitted, self.get_meta())
  File "/usr/local/lib/python3.7/site-packages/django/db/models/sql/query.py", line 1420, in names_to_path
    "Choices are: %s" % (name, ", ".join(available)))
django.core.exceptions.FieldError: Cannot resolve keyword 'is_done' into field. Choices are: created_time, file_path, file_size, filename, id, last_modified_time
2020-10-31 11:59:20,683 ERROR django.request:140150956881664 - Internal Server Error: /taskstest
Traceback (most recent call last):
  File "/usr/local/lib/python3.7/site-packages/django/core/handlers/exception.py", line 34, in inner
    response = get_response(request)
  File "/usr/local/lib/python3.7/site-packages/django/core/handlers/base.py", line 115, in _get_response
    response = self.process_exception_by_middleware(e, request)
  File "/usr/local/lib/python3.7/site-packages/django/core/handlers/base.py", line 113, in _get_response
    response = wrapped_callback(request, *callback_args, **callback_kwargs)
  File "/app/prs_dev/modules/views/event_collector.py", line 45, in main
    observer.start()
  File "/usr/local/lib/python3.7/site-packages/watchdog/observers/api.py", line 260, in start
    emitter.start()
  File "/usr/local/lib/python3.7/site-packages/watchdog/utils/__init__.py", line 110, in start
    self.on_thread_start()
  File "/usr/local/lib/python3.7/site-packages/watchdog/observers/inotify.py", line 121, in on_thread_start
    self._inotify = InotifyBuffer(path, self.watch.is_recursive)
  File "/usr/local/lib/python3.7/site-packages/watchdog/observers/inotify_buffer.py", line 35, in __init__
    self._inotify = Inotify(path, recursive)
  File "/usr/local/lib/python3.7/site-packages/watchdog/observers/inotify_c.py", line 203, in __init__
    self._add_watch(path, event_mask)
  File "/usr/local/lib/python3.7/site-packages/watchdog/observers/inotify_c.py", line 412, in _add_watch
    Inotify._raise_error()
  File "/usr/local/lib/python3.7/site-packages/watchdog/observers/inotify_c.py", line 432, in _raise_error
    raise OSError(err, os.strerror(err))
FileNotFoundError: [Errno 2] No such file or directory
